Workbook

Sheet Case 1
B2: Hardness—Spearman's ρ
B3: Predictor | C3: Expected Contribution to target | D3: Spearman's |ρ| | E3: |ρ| aligned to expectations? | F3: Normalized Feature Importance Metric (NFIM) | G3: NFIM Aligned to expectations? | H3: EDA rank and FIM algined?
B4: % Zirconium | C4: Major | D4: 0.67 | E4: =IF($C4="Major", IF($D4 >= 0.3, "Yes", "No"), IF($D4 < 0.3, "Yes", "No")) -> Yes | F4: 0.56902655 | G4: =IF($C4="Major", IF($F4 > 0.1, "Yes", "No"), IF($F4 <= 0.1, "Yes", "No")) -> Yes | H4: =IF(E4 = G4, "Yes", "No") -> Yes
B5: % Cerium | C5: Major | D5: 0.4 | E5: =IF($C5="Major", IF($D5 >= 0.3, "Yes", "No"), IF($D5 < 0.3, "Yes", "No")) -> Yes | F5: 0.039823009 | G5: =IF($C5="Major", IF($F5 > 0.1, "Yes", "No"), IF($F5 <= 0.1, "Yes", "No")) -> No | H5: =IF(E5 = G5, "Yes", "No") -> No
B6: Aging time | C6: Major | D6: 0.4 | E6: =IF($C6="Major", IF($D6 >= 0.3, "Yes", "No"), IF($D6 < 0.3, "Yes", "No")) -> Yes | F6: 0.33097345 | G6: =IF($C6="Major", IF($F6 > 0.1, "Yes", "No"), IF($F6 <= 0.1, "Yes", "No")) -> Yes | H6: =IF(E6 = G6, "Yes", "No") -> Yes
B7: % Chromium | C7: Minor | D7: 0.27 | E7: =IF($C7="Major", IF($D7 >= 0.3, "Yes", "No"), IF($D7 < 0.3, "Yes", "No")) -> Yes | F7: 0.059292035 | G7: =IF($C7="Major", IF($F7 > 0.1, "Yes", "No"), IF($F7 <= 0.1, "Yes", "No")) -> Yes | H7: =IF(E7 = G7, "Yes", "No") -> Yes
B8: % Lanthanum | C8: Minor | D8: 0.22 | E8: =IF($C8="Major", IF($D8 >= 0.3, "Yes", "No"), IF($D8 < 0.3, "Yes", "No")) -> Yes | F8: 0.024778761 | G8: =IF($C8="Major", IF($F8 > 0.1, "Yes", "No"), IF($F8 <= 0.1, "Yes", "No")) -> Yes | H8: =IF(E8 = G8, "Yes", "No") -> Yes
B10: Major Predictors | C10: =COUNTIF($C4:$C8,"Major") -> 3
B11: Minor Predictors | C11: =COUNTIF($C4:$C8,"Minor") -> 2
B12: Total Number of Predictors | C12: =SUM(C10:C11) -> 5
B13: Predictors having EDA aligned to expectations | C13: =COUNTIF(E4:E8, "Yes") -> 5
B14: Predictors having NFIM aligned to expectations | C14: =COUNTIF(G4:G8, "Yes") -> 4
B15: Predictors having EDA and NFIM aligned | C15: =COUNTIF(H4:H8, "Yes") -> 4

Sheet Case 2
B2: Conductivity—Spearman's ρ
B3: Predictor | C3: Expected Contribution to target | D3: Spearman's |ρ| | E3: |ρ| aligned to expectations? | F3: Normalized Feature Importance Metric (NFIM) | G3: NFIM Aligned to expectations? | H3: EDA rank and FIM rank agree?
B4: Aging time | C4: Major | D4: 0.82 | E4: =IF($C4="Major", IF($D4 >= 0.3, "Yes", "No"), IF($D4 < 0.3, "Yes", "No")) -> Yes | F4: 0.83 | G4: =IF($C4="Major", IF($F4 > 0.1, "Yes", "No"), IF($F4 <= 0.1, "Yes", "No")) -> Yes | H4: =IF(E4 = G4, "Yes", "No") -> Yes
B5: % Zirconium | C5: Minor | D5: 0.2 | E5: =IF($C5="Major", IF($D5 >= 0.3, "Yes", "No"), IF($D5 < 0.3, "Yes", "No")) -> Yes | F5: =7.927927928/100 -> 0.079279279 | G5: =IF($C5="Major", IF($F5 > 0.1, "Yes", "No"), IF($F5 <= 0.1, "Yes", "No")) -> Yes | H5: =IF(E5 = G5, "Yes", "No") -> Yes
B6: % Cerium | C6: Minor | D6: 0.08 | E6: =IF($C6="Major", IF($D6 >= 0.3, "Yes", "No"), IF($D6 < 0.3, "Yes", "No")) -> Yes | F6: =3.027027027/100 -> 0.03027027 | G6: =IF($C6="Major", IF($F6 > 0.1, "Yes", "No"), IF($F6 <= 0.1, "Yes", "No")) -> Yes | H6: =IF(E6 = G6, "Yes", "No") -> Yes
B7: % Chromium | C7: Minor | D7: 0.12 | E7: =IF($C7="Major", IF($D7 >= 0.3, "Yes", "No"), IF($D7 < 0.3, "Yes", "No")) -> Yes | F7: =5.765765766/100 -> 0.057657658 | G7: =IF($C7="Major", IF($F7 > 0.1, "Yes", "No"), IF($F7 <= 0.1, "Yes", "No")) -> Yes | H7: =IF(E7 = G7, "Yes", "No") -> Yes
B8: % Lanthanum | C8: Minor | D8: 0.05 | E8: =IF($C8="Major", IF($D8 >= 0.3, "Yes", "No"), IF($D8 < 0.3, "Yes", "No")) -> Yes | F8: =0.864864865/100 -> 0.0086486487 | G8: =IF($C8="Major", IF($F8 > 0.1, "Yes", "No"), IF($F8 <= 0.1, "Yes", "No")) -> Yes | H8: =IF(E8 = G8, "Yes", "No") -> Yes
B10: Major Predictors | C10: =COUNTIF($C4:$C8,"Major") -> 1
B11: Minor Predictors | C11: =COUNTIF($C4:$C8,"Minor") -> 4
B12: Total Number of Predictors | C12: =SUM(C10:C11) -> 5
B13: Predictors having EDA aligned to expectations | C13: =COUNTIF(E4:E8, "Yes") -> 5
B14: Predictors having NFIM aligned to expectations | C14: =COUNTIF(G4:G8, "Yes") -> 5
B15: Predictors having EDA and NFIM aligned | C15: =COUNTIF(H4:H8, "Yes") -> 5

Sheet Case 3
B2: Adsorption—Spearman's ρ
B3: Predictor | C3: Expected Contribution to target | D3: Spearman's |ρ| | E3: |ρ| aligned to expectations? | F3: Normalized Feature Importance Metric (NFIM) | G3: NFIM Aligned to expectations? | H3: EDA rank and FIM rank agree?
B4: Concentration (of TPU) | C4: Major | D4: 0.48 | E4: =IF($C4="Major", IF($D4 >= 0.3, "Yes", "No"), IF($D4 < 0.3, "Yes", "No")) -> Yes | F4: =100/128 -> 0.78125 | G4: =IF($C4="Major", IF($F4 > 0.1, "Yes", "No"), IF($F4 <= 0.1, "Yes", "No")) -> Yes | H4: =IF(E4 = G4, "Yes", "No") -> Yes
B5: Temperature | C5: Major | D5: 0.23 | E5: =IF($C5="Major", IF($D5 >= 0.3, "Yes", "No"), IF($D5 < 0.3, "Yes", "No")) -> No | F5: =1/128 -> 0.0078125 | G5: =IF($C5="Major", IF($F5 > 0.1, "Yes", "No"), IF($F5 <= 0.1, "Yes", "No")) -> No | H5: =IF(E5 = G5, "Yes", "No") -> Yes
B6: Time | C6: Minor | D6: 0.13 | E6: =IF($C6="Major", IF($D6 >= 0.3, "Yes", "No"), IF($D6 < 0.3, "Yes", "No")) -> Yes | F6: =4/128 -> 0.03125 | G6: =IF($C6="Major", IF($F6 > 0.1, "Yes", "No"), IF($F6 <= 0.1, "Yes", "No")) -> Yes | H6: =IF(E6 = G6, "Yes", "No") -> Yes
B7: Mixture Ratio | C7: Major | D7: 0 | E7: =IF($C7="Major", IF($D7 >= 0.3, "Yes", "No"), IF($D7 < 0.3, "Yes", "No")) -> No | F7: =23/128 -> 0.1796875 | G7: =IF($C7="Major", IF($F7 > 0.1, "Yes", "No"), IF($F7 <= 0.1, "Yes", "No")) -> Yes | H7: =IF(E7 = G7, "Yes", "No") -> No
B10: Major Predictors | C10: =COUNTIF($C4:$C8,"Major") -> 3
B11: Minor Predictors | C11: =COUNTIF($C4:$C8,"Minor") -> 1
B12: Total Number of Predictors | C12: =SUM(C10:C11) -> 4
B13: Predictors having EDA aligned to expectations | C13: =COUNTIF(E4:E7, "Yes") -> 2
B14: Predictors having NFIM aligned to expectations | C14: =COUNTIF(G4:G7, "Yes") -> 3
B15: Predictors having EDA and NFIM aligned | C15: =COUNTIF(H4:H7, "Yes") -> 3

Sheet Case 4
B2: H2 Catalyst—Spearman's ρ
B3: Predictor | C3: Expected Contribution to target | D3: Spearman's |ρ| | E3: |ρ| aligned to expectations? | F3: Normalized Feature Importance Metric (NFIM) | G3: NFIM Aligned to expectations? | H3: EDA rank and FIM rank agree?
B4: Volume | C4: Minor | D4: 0.15 | E4: =IF(C4="Major", IF($D4 >= 0.3, "Yes", "No"), IF($D4 < 0.3, "Yes", "No")) -> Yes | F4: =0.09/0.999 -> 0.09009009 | G4: =IF(C4="Major", IF($F4 > 0.1, "Yes", "No"), IF($F4 <= 0.1, "Yes", "No")) -> Yes | H4: =IF(E4 = G4, "Yes", "No") -> Yes
B5: Weighted Atomic Radius | C5: Minor | D5: 0.029 | E5: =IF(C5="Major", IF($D5 >= 0.3, "Yes", "No"), IF($D5 < 0.3, "Yes", "No")) -> Yes | F5: =0.057/0.999 -> 0.057057057 | G5: =IF(C5="Major", IF($F5 > 0.1, "Yes", "No"), IF($F5 <= 0.1, "Yes", "No")) -> Yes | H5: =IF(E5 = G5, "Yes", "No") -> Yes
B6: Generalized Coordination Number | C6: Major | D6: 0.28 | E6: =IF(C6="Major", IF($D6 >= 0.3, "Yes", "No"), IF($D6 < 0.3, "Yes", "No")) -> No | F6: 0.19 | G6: =IF(C6="Major", IF($F6 > 0.1, "Yes", "No"), IF($F6 <= 0.1, "Yes", "No")) -> Yes | H6: =IF(E6 = G6, "Yes", "No") -> No
B7: Weighted Electronegativity | C7: Major | D7: 0.24 | E7: =IF(C7="Major", IF($D7 >= 0.3, "Yes", "No"), IF($D7 < 0.3, "Yes", "No")) -> No | F7: 0.158 | G7: =IF(C7="Major", IF($F7 > 0.1, "Yes", "No"), IF($F7 <= 0.1, "Yes", "No")) -> Yes | H7: =IF(E7 = G7, "Yes", "No") -> No
B8: Weighted Ionization Energy | C8: Major | D8: 0.17 | E8: =IF(C8="Major", IF($D8 >= 0.3, "Yes", "No"), IF($D8 < 0.3, "Yes", "No")) -> No | F8: 0.056 | G8: =IF(C8="Major", IF($F8 > 0.1, "Yes", "No"), IF($F8 <= 0.1, "Yes", "No")) -> No | H8: =IF(E8 = G8, "Yes", "No") -> Yes
B9: S_A | C9: Major | D9: 0.18 | E9: =IF(C9="Major", IF($D9 >= 0.3, "Yes", "No"), IF($D9 < 0.3, "Yes", "No")) -> No | F9: =0.143/0.999 -> 0.14314314 | G9: =IF(C9="Major", IF($F9 > 0.1, "Yes", "No"), IF($F9 <= 0.1, "Yes", "No")) -> Yes | H9: =IF(E9 = G9, "Yes", "No") -> No
B10: S_B | C10: Minor | D10: 0.034 | E10: =IF(C10="Major", IF($D10 >= 0.3, "Yes", "No"), IF($D10 < 0.3, "Yes", "No")) -> Yes | F10: =0.057/0.999 -> 0.057057057 | G10: =IF(C10="Major", IF($F10 > 0.1, "Yes", "No"), IF($F10 <= 0.1, "Yes", "No")) -> Yes | H10: =IF(E10 = G10, "Yes", "No") -> Yes
B11: ψ | C11: Major | D11: 0.15 | E11: =IF(C11="Major", IF($D11 >= 0.3, "Yes", "No"), IF($D11 < 0.3, "Yes", "No")) -> No | F11: 0.212 | G11: =IF(C11="Major", IF($F11 > 0.1, "Yes", "No"), IF($F11 <= 0.1, "Yes", "No")) -> Yes | H11: =IF(E11 = G11, "Yes", "No") -> No
B12: facet | C12: Minor | D12: 0.03 | E12: =IF(C12="Major", IF($D12 >= 0.3, "Yes", "No"), IF($D12 < 0.3, "Yes", "No")) -> Yes | F12: =0.036/0.999 -> 0.036036036 | G12: =IF(C12="Major", IF($F12 > 0.1, "Yes", "No"), IF($F12 <= 0.1, "Yes", "No")) -> Yes | H12: =IF(E12 = G12, "Yes", "No") -> Yes
B20: Major Predictors | C20: =COUNTIF(C4:C12,"Major") -> 5
B21: Minor Predictors | C21: =COUNTIF(C4:C12,"Minor") -> 4
B22: Total Number of Predictors | C22: =SUM(C20:C21) -> 9
B23: Predictors having EDA aligned to expectations | C23: =COUNTIF(E4:E12, "Yes") -> 4
B24: Predictors having NFIM aligned to expectations | C24: =COUNTIF(G4:G12, "Yes") -> 8
B25: Predictors having EDA and NFIM aligned | C25: =COUNTIF(H4:H12, "Yes") -> 5

Sheet Case 5A
B2: IsVCO—Decision Stump
B3: Predictor | C3: Expected Contribution to target | D3: p-value | E3: p -value aligned to expectations? | F3: Normalized Feature Importance Metric (NFIM) | G3: NFIM Aligned to expectations? | H3: EDA alignment and NFIM alignment agree?
B4: UV-Vis Absorbance at 278 nm | C4: Major | D4: 2.751181e-39 | E4: =IF($C4 = "Major", IF($D4 < 0.05, "Yes", "No"), IF($D4 >= 0.05, "Yes", "No")) -> Yes | F4: 1 | G4: =IF($C4="Major", IF($F4 > 0.1, "Yes", "No"), IF($F4 <= 0.1, "Yes", "No")) -> Yes | H4: =IF(E4 = G4, "Yes", "No") -> Yes
B5: Diglyceride signal ratio | C5: Major | D5: 6.667e-08 | E5: =IF($C5 = "Major", IF($D5 < 0.05, "Yes", "No"), IF($D5 >= 0.05, "Yes", "No")) -> Yes | F5: 0 | G5: =IF($C5="Major", IF($F5 > 0.1, "Yes", "No"), IF($F5 <= 0.1, "Yes", "No")) -> No | H5: =IF(E5 = G5, "Yes", "No") -> No
B6: Unsaturated carbon signal ratio | C6: Minor | D6: 1.38644e-13 | E6: =IF($C6 = "Major", IF($D6 < 0.05, "Yes", "No"), IF($D6 >= 0.05, "Yes", "No")) -> No | F6: 0 | G6: =IF($C6="Major", IF($F6 > 0.1, "Yes", "No"), IF($F6 <= 0.1, "Yes", "No")) -> Yes | H6: =IF(E6 = G6, "Yes", "No") -> No
B8: Major Predictors | C8: =COUNTIF($C2:$C6,"Major") -> 2
B9: Minor Predictors | C9: =COUNTIF($C2:$C6,"Minor") -> 1
B10: Total Number of Predictors | C10: =SUM(C8:C9) -> 3
B11: Predictors having EDA aligned to expectations | C11: =COUNTIF(E4:E6, "Yes") -> 2
B12: Predictors having NFIM aligned to expectations | C12: =COUNTIF($G4:$G6, "Yes") -> 2
B13: Predictors having EDA and NFIM aligned | C13: =COUNTIF($H4:$H6, "Yes") -> 1

Sheet Case 5B
B2: IsVCO—Logistic Regression
B3: Predictor | C3: Expected Contribution to target | D3: p-value | E3: p-value aligned to expectations? | F3: Normalized Feature Importance Metric (NFIM) | G3: NFIM Aligned to expectations? | H3: EDA alignment and NFIM alignment agree?
B4: UV-Vis Absorbance at 278 nm | C4: Major | D4: 2.751181e-39 | E4: =IF($C4 = "Major", IF($D4 < 0.05, "Yes", "No"), IF($D4 >= 0.05, "Yes", "No")) -> Yes | F4: 0.532 | G4: =IF($C4="Major", IF($F4 > 0.1, "Yes", "No"), IF($F4 <= 0.1, "Yes", "No")) -> Yes | H4: =IF(E4 = G4, "Yes", "No") -> Yes
B5: Diglyceride signal ratio | C5: Major | D5: 6.667e-08 | E5: =IF($C5 = "Major", IF($D5 < 0.05, "Yes", "No"), IF($D5 >= 0.05, "Yes", "No")) -> Yes | F5: 0.2 | G5: =IF($C5="Major", IF($F5 > 0.1, "Yes", "No"), IF($F5 <= 0.1, "Yes", "No")) -> Yes | H5: =IF(E5 = G5, "Yes", "No") -> Yes
B6: Unsaturated carbon signal ratio | C6: Minor | D6: 1.38644e-13 | E6: =IF($C6 = "Major", IF($D6 < 0.05, "Yes", "No"), IF($D6 >= 0.05, "Yes", "No")) -> No | F6: 0.268 | G6: =IF($C6="Major", IF($F6 > 0.1, "Yes", "No"), IF($F6 <= 0.1, "Yes", "No")) -> No | H6: =IF(E6 = G6, "Yes", "No") -> Yes
B9: Major Predictors | C9: =COUNTIF($C2:$C6,"Major") -> 2
B10: Minor Predictors | C10: =COUNTIF($C2:$C6,"Minor") -> 1
B11: Total Number of Predictors | C11: =SUM(C9:C10) -> 3
B12: Predictors having EDA aligned to expectations | C12: =COUNTIF(E4:E6, "Yes") -> 2
B13: Predictors having NFIM aligned to expectations | C13: =COUNTIF($G4:$G6, "Yes") -> 2
B14: Predictors having EDA and NFIM aligned | C14: =COUNTIF($H4:$H6, "Yes") -> 3

Sheet Case 5C
B2: IsVCO—Naïve Bayes
B3: Predictor | C3: Expected Contribution to target | D3: p-value | E3: p aligned to expectations? | F3: Normalized Feature Importance Metric (NFIM) | G3: NFIM Aligned to expectations? | H3: EDA alignment and NFIM alignment agree?
B4: UV-Vis Absorbance at 278 nm | C4: Major | D4: 2.751181e-39 | E4: =IF($C4 = "Major", IF($D4 < 0.05, "Yes", "No"), IF($D4 >= 0.05, "Yes", "No")) -> Yes | F4: 0.9 | G4: =IF($C4="Major", IF($F4 > 0.1, "Yes", "No"), IF($F4 <= 0.1, "Yes", "No")) -> Yes | H4: =IF(E4 = G4, "Yes", "No") -> Yes
B5: Diglyceride signal ratio | C5: Major | D5: 6.667e-08 | E5: =IF($C5 = "Major", IF($D5 < 0.05, "Yes", "No"), IF($D5 >= 0.05, "Yes", "No")) -> Yes | F5: 0.027 | G5: =IF($C5="Major", IF($F5 > 0.1, "Yes", "No"), IF($F5 <= 0.1, "Yes", "No")) -> No | H5: =IF(E5 = G5, "Yes", "No") -> No
B6: Unsaturated carbon signal ratio | C6: Minor | D6: 1.38644e-13 | E6: =IF($C6 = "Major", IF($D6 < 0.05, "Yes", "No"), IF($D6 >= 0.05, "Yes", "No")) -> No | F6: 0.072 | G6: =IF($C6="Major", IF($F6 > 0.1, "Yes", "No"), IF($F6 <= 0.1, "Yes", "No")) -> Yes | H6: =IF(E6 = G6, "Yes", "No") -> No
B8: Major Predictors | C8: =COUNTIF($C2:$C6,"Major") -> 2
B9: Minor Predictors | C9: =COUNTIF($C2:$C6,"Minor") -> 1
B10: Total Number of Predictors | C10: =SUM(C8:C9) -> 3
B11: Predictors having EDA aligned to expectations | C11: =COUNTIF(E4:E6, "Yes") -> 2
B12: Predictors having NFIM aligned to expectations | C12: =COUNTIF($G4:$G6, "Yes") -> 2
B13: Predictors having EDA and NFIM aligned | C13: =COUNTIF($H4:$H6, "Yes") -> 1

Sheet Case 5D
B2: IsVCO—Random Forest
B3: Predictor | C3: Expected Contribution to target | D3: p-value | E3: p aligned to expectations? | F3: Normalized Feature Importance Metric (NFIM) | G3: NFIM Aligned to expectations? | H3: EDA alignment and NFIM alignment agree?
B4: UV-Vis Absorbance at 278 nm | C4: Major | D4: 2.751181e-39 | E4: =IF($C4 = "Major", IF($D4 < 0.05, "Yes", "No"), IF($D4 >= 0.05, "Yes", "No")) -> Yes | F4: 1 | G4: =IF($C4="Major", IF($F4 > 0.1, "Yes", "No"), IF($F4 <= 0.1, "Yes", "No")) -> Yes | H4: =IF(E4 = G4, "Yes", "No") -> Yes
B5: Diglyceride signal ratio | C5: Major | D5: 6.67e-08 | E5: =IF($C5 = "Major", IF($D5 < 0.05, "Yes", "No"), IF($D5 >= 0.05, "Yes", "No")) -> Yes | F5: 0 | G5: =IF($C5="Major", IF($F5 > 0.1, "Yes", "No"), IF($F5 <= 0.1, "Yes", "No")) -> No | H5: =IF(E5 = G5, "Yes", "No") -> No
B6: Unsaturated carbon signal ratio | C6: Minor | D6: 1.38644e-13 | E6: =IF($C6 = "Major", IF($D6 < 0.05, "Yes", "No"), IF($D6 >= 0.05, "Yes", "No")) -> No | F6: 0 | G6: =IF($C6="Major", IF($F6 > 0.1, "Yes", "No"), IF($F6 <= 0.1, "Yes", "No")) -> Yes | H6: =IF(E6 = G6, "Yes", "No") -> No
B8: Major Predictors | C8: =COUNTIF($C2:$C6,"Major") -> 2
B9: Minor Predictors | C9: =COUNTIF($C2:$C6,"Minor") -> 1
B10: Total Number of Predictors | C10: =SUM(C8:C9) -> 3
B11: Predictors having EDA aligned to expectations | C11: =COUNTIF(E4:E6, "Yes") -> 2
B12: Predictors having NFIM aligned to expectations | C12: =COUNTIF($G4:$G6, "Yes") -> 2
B13: Predictors having EDA and NFIM aligned | C13: =COUNTIF($H4:$H6, "Yes") -> 1

Sheet Case 6
B2: Explosives
B3: Predictor | C3: Expected Contribution to target | D3: p-value | E3: p aligned to expectations? | F3: Normalized Feature Importance Metric (NFIM) | G3: NFIM Aligned to expectations? | H3: EDA alignment and NFIM alignment agree?
B4: KMF | C4: Major | D4: 0.00044766 | E4: =IF($C4 = "Major", IF($D4 < 0.05, "Yes", "No"), IF($D4 >= 0.05, "Yes", "No")) -> Yes | F4: 0.093984605 | G4: =IF($C4="Major", IF($F4 > 0.1, "Yes", "No"), IF($F4 <= 0.1, "Yes", "No")) -> No | H4: =IF(OR( (AND(D4 < 0.05, F4 > 0.1)), (AND(D4 >= 0.05, F4 <= 0.1))), "Yes", "No") -> No
B5: Class I TBs | C5: Major | D5: 0.00012039 | E5: =IF($C5 = "Major", IF($D5 < 0.05, "Yes", "No"), IF($D5 >= 0.05, "Yes", "No")) -> Yes | F5: 0.039094126 | G5: =IF($C5="Major", IF($F5 > 0.1, "Yes", "No"), IF($F5 <= 0.1, "Yes", "No")) -> No | H5: =IF(OR( (AND(D5 < 0.05, F5 > 0.1)), (AND(D5 >= 0.05, F5 <= 0.1))), "Yes", "No") -> No
B6: Class II TBs | C6: Major | D6: 0.0094777 | E6: =IF($C6 = "Major", IF($D6 < 0.05, "Yes", "No"), IF($D6 >= 0.05, "Yes", "No")) -> Yes | F6: 0.03915714 | G6: =IF($C6="Major", IF($F6 > 0.1, "Yes", "No"), IF($F6 <= 0.1, "Yes", "No")) -> No | H6: =IF(OR( (AND(D6 < 0.05, F6 > 0.1)), (AND(D6 >= 0.05, F6 <= 0.1))), "Yes", "No") -> No
B7: Number of N3 | C7: Major | D7: 6.8496e-07 | E7: =IF($C7 = "Major", IF($D7 < 0.05, "Yes", "No"), IF($D7 >= 0.05, "Yes", "No")) -> Yes | F7: 0.051802959 | G7: =IF($C7="Major", IF($F7 > 0.1, "Yes", "No"), IF($F7 <= 0.1, "Yes", "No")) -> No | H7: =IF(OR( (AND(D7 < 0.05, F7 > 0.1)), (AND(D7 >= 0.05, F7 <= 0.1))), "Yes", "No") -> No
B8: Number of N | C8: Minor | D8: 0.065124 | E8: =IF($C8 = "Major", IF($D8 < 0.05, "Yes", "No"), IF($D8 >= 0.05, "Yes", "No")) -> Yes | F8: 0.055230701 | G8: =IF($C8="Major", IF($F8 > 0.1, "Yes", "No"), IF($F8 <= 0.1, "Yes", "No")) -> Yes | H8: =IF(OR( (AND(D8 < 0.05, F8 > 0.1)), (AND(D8 >= 0.05, F8 <= 0.1))), "Yes", "No") -> Yes
B9: Number of C | C9: Minor | D9: 0.00080958 | E9: =IF($C9 = "Major", IF($D9 < 0.05, "Yes", "No"), IF($D9 >= 0.05, "Yes", "No")) -> No | F9: 0.083826427 | G9: =IF($C9="Major", IF($F9 > 0.1, "Yes", "No"), IF($F9 <= 0.1, "Yes", "No")) -> Yes | H9: =IF(OR( (AND(D9 < 0.05, F9 > 0.1)), (AND(D9 >= 0.05, F9 <= 0.1))), "Yes", "No") -> No
B10: H Bond Ratio | C10: Major | D10: 1.5845e-07 | E10: =IF($C10 = "Major", IF($D10 < 0.05, "Yes", "No"), IF($D10 >= 0.05, "Yes", "No")) -> Yes | F10: 0.082912543 | G10: =IF($C10="Major", IF($F10 > 0.1, "Yes", "No"), IF($F10 <= 0.1, "Yes", "No")) -> No | H10: =IF(OR( (AND(D10 < 0.05, F10 > 0.1)), (AND(D10 >= 0.05, F10 <= 0.1))), "Yes", "No") -> No
B11: Oxygen Balance | C11: Major | D11: 1.9613e-24 | E11: =IF($C11 = "Major", IF($D11 < 0.05, "Yes", "No"), IF($D11 >= 0.05, "Yes", "No")) -> Yes | F11: 0.24175624 | G11: =IF($C11="Major", IF($F11 > 0.1, "Yes", "No"), IF($F11 <= 0.1, "Yes", "No")) -> Yes | H11: =IF(OR( (AND(D11 < 0.05, F11 > 0.1)), (AND(D11 >= 0.05, F11 <= 0.1))), "Yes", "No") -> Yes
B12: NO2 adj to NO2 | C12: Minor | D12: 0.91956 | E12: =IF($C12 = "Major", IF($D12 < 0.05, "Yes", "No"), IF($D12 >= 0.05, "Yes", "No")) -> Yes | F12: 0.010286512 | G12: =IF($C12="Major", IF($F12 > 0.1, "Yes", "No"), IF($F12 <= 0.1, "Yes", "No")) -> Yes | H12: =IF(OR( (AND(D12 < 0.05, F12 > 0.1)), (AND(D12 >= 0.05, F12 <= 0.1))), "Yes", "No") -> Yes
B13: NO2 adj to NH2 | C13: Major | D13: 3.1108e-05 | E13: =IF($C13 = "Major", IF($D13 < 0.05, "Yes", "No"), IF($D13 >= 0.05, "Yes", "No")) -> Yes | F13: 0.014729697 | G13: =IF($C13="Major", IF($F13 > 0.1, "Yes", "No"), IF($F13 <= 0.1, "Yes", "No")) -> No | H13: =IF(OR( (AND(D13 < 0.05, F13 > 0.1)), (AND(D13 >= 0.05, F13 <= 0.1))), "Yes", "No") -> No
B14: NO2 adj to CO | C14: Minor | D14: 0.42743 | E14: =IF($C14 = "Major", IF($D14 < 0.05, "Yes", "No"), IF($D14 >= 0.05, "Yes", "No")) -> Yes | F14: 0.0058362673 | G14: =IF($C14="Major", IF($F14 > 0.1, "Yes", "No"), IF($F14 <= 0.1, "Yes", "No")) -> Yes | H14: =IF(OR( (AND(D14 < 0.05, F14 > 0.1)), (AND(D14 >= 0.05, F14 <= 0.1))), "Yes", "No") -> Yes
B15: NO2 adj to CH3 | C15: Minor | D15: 0.21348 | E15: =IF($C15 = "Major", IF($D15 < 0.05, "Yes", "No"), IF($D15 >= 0.05, "Yes", "No")) -> Yes | F15: 0.0029031861 | G15: =IF($C15="Major", IF($F15 > 0.1, "Yes", "No"), IF($F15 <= 0.1, "Yes", "No")) -> Yes | H15: =IF(OR( (AND(D15 < 0.05, F15 > 0.1)), (AND(D15 >= 0.05, F15 <= 0.1))), "Yes", "No") -> Yes
... B22: TPSA | C22: Minor | D22: 8.3077e-05 | E22: =IF($C22 = "Major", IF($D22 < 0.05, "Yes", "No"), IF($D22 >= 0.05, "Yes", "No")) -> No | F22: 0.077235776 | G22: =IF($C22="Major", IF($F22 > 0.1, "Yes", "No"), IF($F22 <= 0.1, "Yes", "No")) -> Yes | H22: =IF(OR( (AND(D22 < 0.05, F22 > 0.1)), (AND(D22 >= 0.05, F22 <= 0.1))), "Yes", "No") -> No
B25: Major Predictors | C25: =COUNTIF($C4:$C22,"Major") -> 10
B26: Minor Predictors | C26: =COUNTIF($C4:$C22,"Minor") -> 9
B27: Total Number of Predictors | C27: =SUM(C25:C26) -> 19
B28: Predictors having EDA aligned to expectations | C28: =COUNTIF(E4:E22, "Yes") -> 17
B29: Predictors having NFIM aligned to expectations | C29: =COUNTIF(G4:G22, "Yes") -> 10
B30: Predictors having EDA and NFIM aligned | C30: =COUNTIF(H4:H22, "Yes") -> 8

Sheet Alignment Score Computation
A3: Case 1 | F3: Case 2
A4: Ante-hoc aligned | B4: ='Case 1'!C13 -> 5 | F4: Ante-hoc aligned | G4: ='Case 2'!C13 -> 5
A5: Post-hoc aligned | B5: ='Case 1'!C14 -> 4 | F5: Post-hoc aligned | G5: ='Case 2'!C14 -> 5
A6: EDA-FIM aligned | B6: ='Case 1'!C15 -> 4 | F6: EDA-FIM aligned | G6: ='Case 2'!C15 -> 5
A7: Total number of predictors | B7: ='Case 1'!C12 -> 5 | F7: Total number of predictors | G7: ='Case 2'!C12 -> 5
A9: Score | B9: Points | C9: Max. Possible points | D9: Percentage | F9: Score | G9: Points | H9: Max. Possible points | I9: Percentage
A10: Ante-hoc Alignment | B10: =B4 -> 5 | C10: =B7 -> 5 | D10: =100*B10/C10 -> 100 | F10: Ante-hoc Alignment | G10: =G4 -> 5 | H10: =G7 -> 5 | I10: =100*G10/H10 -> 100
A11: Post-hoc Alignment | B11: =B5 -> 4 | C11: =B7 -> 5 | D11: =100*B11/C11 -> 80 | F11: Post-hoc Alignment | G11: =G5 -> 5 | H11: =G7 -> 5 | I11: =100*G11/H11 -> 100
A12: EDA-FIM alignment | B12: =ROUND((0.5*(LOG10(B6/B7)+1)*B7)*10,0)/10 -> 2.3 | C12: =B7*0.5 -> 2.5 | D12: =100*B12/C12 -> 92 | F12: EDA-FIM alignment | G12: =ROUND((0.5*(LOG10(G6/G7)+1)*G7)*10,0)/10 -> 2.5 | H12: =G7*0.5 -> 2.5 | I12: =100*G12/H12 -> 100
A13: Total | B13: =ROUND(SUM(B10:B12)*10,0)/10 -> 11.3 | C13: =SUM(C10:C12) -> 12.5 | D13: =100*B13/C13 -> 90.4 | F13: Total | G13: =ROUND(SUM(G10:G12)*10,0)/10 -> 12.5 | H13: =SUM(H10:H12) -> 12.5 | I13: =100*G13/H13 -> 100
A17: Case 3 | F17: Case 4
A18: Ante-hoc aligned | B18: ='Case 3'!C13 -> 2 | F18: Ante-hoc aligned | G18: ='Case 4'!C23 -> 4
A19: Post-hoc aligned | B19: ='Case 3'!C14 -> 3 | F19: Post-hoc aligned | G19: ='Case 4'!C24 -> 8
A20: EDA-FIM aligned | B20: ='Case 3'!C15 -> 3 | F20: EDA-FIM aligned | G20: ='Case 4'!C25 -> 5
A21: Total number of predictors | B21: ='Case 3'!C12 -> 4 | F21: Total number of predictors | G21: ='Case 4'!C22 -> 9
A23: Score | B23: Points | C23: Max. Possible points | D23: Percentage | F23: Score | G23: Points | H23: Max. Possible points | I23: Percentage
A24: Ante-hoc Alignment | B24: =B18 -> 2 | C24: =B21 -> 4 | D24: =100*B24/C24 -> 50 | F24: Ante-hoc Alignment | G24: =G18 -> 4 | H24: =G21 -> 9 | I24: =100*G24/H24 -> 44.444444
A25: Post-hoc Alignment | B25: =B19 -> 3 | C25: =B21 -> 4 | D25: =100*B25/C25 -> 75 | F25: Post-hoc Alignment | G25: =G19 -> 8 | H25: =G21 -> 9 | I25: =100*G25/H25 -> 88.888889
A26: EDA-FIM alignment | B26: =ROUND((0.5*(LOG10(B20/B21)+1)*B21)*10,0)/10 -> 1.8 | C26: =B21*0.5 -> 2 | D26: =100*B26/C26 -> 90 | F26: EDA-FIM alignment | G26: =ROUND((0.5*(LOG10(G20/G21)+1)*G21)*10,0)/10 -> 3.4 | H26: =G21*0.5 -> 4.5 | I26: =100*G26/H26 -> 75.555556
A27: Total | B27: =ROUND(SUM(B24:B26)*10,0)/10 -> 6.8 | C27: =SUM(C24:C26) -> 10 | D27: =100*B27/C27 -> 68 | F27: Total | G27: =ROUND(SUM(G24:G26)*10,0)/10 -> 15.4 | H27: =SUM(H24:H26) -> 22.5 | I27: =100*G27/H27 -> 68.444444
A31: Case 5A | F31: Case 5B
A32: Ante-hoc aligned | B32: ='Case 5A'!C11 -> 2 | F32: Ante-hoc aligned | G32: ='Case 5B'!C12 -> 2
A33: Post-hoc aligned | B33: ='Case 5A'!C12 -> 2 | F33: Post-hoc aligned | G33: ='Case 5B'!C13 -> 2
A34: EDA-FIM aligned | B34: ='Case 5A'!C13 -> 1 | F34: EDA-FIM aligned | G34: ='Case 5B'!C14 -> 3
A35: Total number of predictors | B35: ='Case 5A'!C10 -> 3 | F35: Total number of predictors | G35: ='Case 5B'!C11 -> 3
A37: Score | B37: Points | C37: Max. Possible points | D37: Percentage | F37: Score | G37: Points | H37: Max. Possible points | I37: Percentage
A38: Ante-hoc Alignment | B38: =B32 -> 2 | C38: =B35 -> 3 | D38: =100*B38/C38 -> 66.666667 | F38: Ante-hoc Alignment | G38: =G32 -> 2 | H38: =G35 -> 3 | I38: =100*G38/H38 -> 66.666667
A39: Post-hoc Alignment | B39: =B33 -> 2 | C39: =B35 -> 3 | D39: =100*B39/C39 -> 66.666667 | F39: Post-hoc Alignment | G39: =G33 -> 2 | H39: =G35 -> 3 | I39: =100*G39/H39 -> 66.666667
A40: EDA-FIM alignment | B40: =ROUND((0.5*(LOG10(B34/B35)+1)*B35)*10,0)/10 -> 0.8 | C40: =B35*0.5 -> 1.5 | D40: =100*B40/C40 -> 53.333333 | F40: EDA-FIM alignment | G40: =ROUND((0.5*(LOG10(G34/G35)+1)*G35)*10,0)/10 -> 1.5 | H40: =G35*0.5 -> 1.5 | I40: =100*G40/H40 -> 100
A41: Total | B41: =ROUND(SUM(B38:B40)*10,0)/10 -> 4.8 | C41: =SUM(C38:C40) -> 7.5 | D41: =100*B41/C41 -> 64 | F41: Total | G41: =ROUND(SUM(G38:G40)*10,0)/10 -> 5.5 | H41: =SUM(H38:H40) -> 7.5 | I41: =100*G41/H41 -> 73.333333
A43: Case 5C | F43: Case 5D
A44: Ante-hoc aligned | B44: ='Case 5C'!C11 -> 2 | F44: Ante-hoc aligned | G44: ='Case 5D'!C11 -> 2
A45: Post-hoc aligned | B45: ='Case 5C'!C12 -> 2 | F45: Post-hoc aligned | G45: ='Case 5D'!C12 -> 2
A46: EDA-FIM aligned | B46: ='Case 5C'!C13 -> 1 | F46: EDA-FIM aligned | G46: ='Case 5D'!C13 -> 1
A47: Total number of predictors | B47: ='Case 5C'!C10 -> 3 | F47: Total number of predictors | G47: ='Case 5D'!C10 -> 3
A49: Score | B49: Points | C49: Max. Possible points | D49: Percentage | F49: Score | G49: Points | H49: Max. Possible points | I49: Percentage
A50: Ante-hoc Alignment | B50: =B44 -> 2 | C50: =B47 -> 3 | D50: =100*B50/C50 -> 66.666667 | F50: Ante-hoc Alignment | G50: =G44 -> 2 | H50: =G47 -> 3 | I50: =100*G50/H50 -> 66.666667
A51: Post-hoc Alignment | B51: =B45 -> 2 | C51: =B47 -> 3 | D51: =100*B51/C51 -> 66.666667 | F51: Post-hoc Alignment | G51: =G45 -> 2 | H51: =G47 -> 3 | I51: =100*G51/H51 -> 66.666667
A52: EDA-FIM alignment | B52: =ROUND((0.5*(LOG10(B46/B47)+1)*B47)*10,0)/10 -> 0.8 | C52: =B47*0.5 -> 1.5 | D52: =100*B52/C52 -> 53.333333 | F52: EDA-FIM alignment | G52: =ROUND((0.5*(LOG10(G46/G47)+1)*G47)*10,0)/10 -> 0.8 | H52: =G47*0.5 -> 1.5 | I52: =100*G52/H52 -> 53.333333
A53: Total | B53: =ROUND(SUM(B50:B52)*10,0)/10 -> 4.8 | C53: =SUM(C50:C52) -> 7.5 | D53: =100*B53/C53 -> 64 | F53: Total | G53: =ROUND(SUM(G50:G52)*10,0)/10 -> 4.8 | H53: =SUM(H50:H52) -> 7.5 | I53: =100*G53/H53 -> 64
...

Sheet Alignment Scores Summary
B3: Ante-Hoc | C3: Post-Hoc | D3: EDA-FIM | E3: Total Alignment Score (%)
A4: Case 1 | B4: ='Alignment Score Computation'!D10*0.4 -> 40 | C4: ='Alignment Score Computation'!D11*0.4 -> 32 | D4: ='Alignment Score Computation'!D12*0.2 -> 18.4 | E4: =SUM(B4:D4) -> 90.4
A5: Case 2 | B5: ='Alignment Score Computation'!I10*0.4 -> 40 | C5: ='Alignment Score Computation'!I11*0.4 -> 40 | D5: ='Alignment Score Computation'!I12*0.2 -> 20 | E5: =SUM(B5:D5) -> 100
A6: Case 3 | B6: ='Alignment Score Computation'!D24*0.4 -> 20 | C6: ='Alignment Score Computation'!D25*0.4 -> 30 | D6: ='Alignment Score Computation'!D26*0.2 -> 18 | E6: =SUM(B6:D6) -> 68
A7: Case 4 | B7: ='Alignment Score Computation'!I24*0.4 -> 17.777778 | C7: ='Alignment Score Computation'!I25*0.4 -> 35.555556 | D7: ='Alignment Score Computation'!I26*0.2 -> 15.111111 | E7: =SUM(B7:D7) -> 68.444444
A8: Case 5A | B8: ='Alignment Score Computation'!D38*0.4 -> 26.666667 | C8: ='Alignment Score Computation'!D39*0.4 -> 26.666667 | D8: ='Alignment Score Computation'!D40*0.2 -> 10.666667 | E8: =SUM(B8:D8) -> 64
A9: Case 5B | B9: ='Alignment Score Computation'!I38*0.4 -> 26.666667 | C9: ='Alignment Score Computation'!I39*0.4 -> 26.666667 | D9: ='Alignment Score Computation'!I40*0.2 -> 20 | E9: =SUM(B9:D9) -> 73.333333
A10: Case 5C | B10: ='Alignment Score Computation'!D50*0.4 -> 26.666667 | C10: ='Alignment Score Computation'!D51*0.4 -> 26.666667 | D10: ='Alignment Score Computation'!D52*0.2 -> 10.666667 | E10: =SUM(B10:D10) -> 64
A11: Case 5D | B11: ='Alignment Score Computation'!I50*0.4 -> 26.666667 | C11: ='Alignment Score Computation'!I51*0.4 -> 26.666667 | D11: ='Alignment Score Computation'!I52*0.2 -> 10.666667 | E11: =SUM(B11:D11) -> 64
A12: Case 6 | B12: ='Alignment Score Computation'!D63*0.4 -> 35.789474 | C12: ='Alignment Score Computation'!D64*0.4 -> 21.052632 | D12: ='Alignment Score Computation'!D65*0.2 -> 12.421053 | E12: =SUM(B12:D12) -> 69.263158
